Workbook
Name ReasonCodes: Lists!$A$2:$A$8
Name Carriers: Lists!$C$2:$C$7
Name Clients: Lists!$E$2:$E$5

Sheet About
B2: Shipment and Inventory Discrepancy Checker
B3: Lekan Lawal | October 2026
B5: Sample data. Every company, SKU, quantity, rate and dollar amount in this file is made up. Carrier names are real Canadian carriers, used only to make the receiving log look realistic.
B7: What it does
B8: Checks three things a warehouse gets wrong most often, and totals them on one dashboard: cycle counts against the system, receipts against the packing slip and PO, and storage invoices against the rate card.
B10: Sheets
B11: Dashboard | C11: Totals, discrepancy counts by type and reason, billing variance by client.
B12: Inventory | C12: Cycle count: system qty vs physical count. Variance, status, dollar impact, reason code.
B13: Receiving | C13: Inbound receipts: PO qty vs packing slip vs qty received. Flags short, over and PO mismatches.
B14: Billing | C14: Monthly storage invoices: pallets x rate vs amount invoiced. Flags variances over the tolerance.
B15: Items | C15: Item master: SKU, description, client, bin location and unit cost. Lookups read from here.
B16: Lists | C16: Dropdown lists, client storage rates and the billing tolerance.
B18: Colour key
B19: 1,250 | C19: Blue text: typed-in values. Change these.
B20: 1,250 | C20: Grey cell: formula. Do not type over it.
B21: Check | C21: Red: needs a look (variance, mismatch or billing difference).
B22: OK | C22: Green text: matches.
B24: How to use it
B25: Step 1 | C25: Enter physical counts in Inventory column D and give every Check row a reason code.
B26: Step 2 | C26: Log receipts in Receiving and storage invoices in Billing. Rates and the tolerance live on Lists.
B27: Step 3 | C27: To add rows, copy the last row down so the grey formula cells come with it.

Sheet Dashboard
B2: Discrepancy Dashboard | H2: Sample data
B3: ="Cycle count to "&TEXT(MAX(Inventory!K2:K500),"d mmm yyyy")&" | Receipts to "&TEXT(MAX(Receiving!A2:A500),"d mmm yyyy")&" | Invoices to "&TEXT(MAX(Billing!A2:A500),"mmm yyyy") -> Cycle count to 30 Sep 2026 | Receipts to 28 Sep 2026 | Invoices to Sep 2026
B5: Items counted | E5: Count discrepancies | H5: Inventory accuracy
B7: =COUNTA(Inventory!$A$2:$A$500) -> 40 | E7: =COUNTIF(Inventory!$F$2:$F$500,"Check") -> 9 | H7: =IF(B7=0,0,1-E7/B7) -> 0.775
B10: Receipts logged | E10: Receiving exceptions | H10: Net count variance ($)
B12: =COUNTA(Receiving!$B$2:$B$500) -> 40 | E12: =COUNTA(Receiving!$B$2:$B$500)-COUNTIF(Receiving!$K$2:$K$500,"OK") -> 8 | H12: =SUM(Inventory!$I$2:$I$500) -> -502.7
B15: Invoices checked | E15: Invoices flagged | H15: Net billing variance ($)
B17: =COUNTA(Billing!$B$2:$B$500) -> 36 | E17: =COUNTIF(Billing!$H$2:$H$500,"Check") -> 4 | H17: =SUMIF(Billing!$H$2:$H$500,"Check",Billing!$G$2:$G$500) -> 514
B21: Discrepancies by type
B22: Type | C22: Count
B23: Count variance | C23: =COUNTIF(Inventory!$F$2:$F$500,"Check") -> 9
B24: Received short | C24: =COUNTIF(Receiving!$K$2:$K$500,"Short") -> 4
B25: Received over | C25: =COUNTIF(Receiving!$K$2:$K$500,"Over") -> 2
B26: PO mismatch | C26: =COUNTIF(Receiving!$K$2:$K$500,"PO mismatch") -> 2
B27: Billing variance | C27: =COUNTIF(Billing!$H$2:$H$500,"Check") -> 4
B35: Count discrepancies by reason
B36: Reason | C36: Count
B37: Count error | C37: =COUNTIF(Inventory!$J$2:$J$500,B37) -> 1
B38: Mis-pick | C38: =COUNTIF(Inventory!$J$2:$J$500,B38) -> 2
B39: Receiving error | C39: =COUNTIF(Inventory!$J$2:$J$500,B39) -> 2
B40: Damaged, not recorded | C40: =COUNTIF(Inventory!$J$2:$J$500,B40) -> 2
B41: Unrecorded transfer | C41: =COUNTIF(Inventory!$J$2:$J$500,B41) -> 1
B42: Theft or loss | C42: =COUNTIF(Inventory!$J$2:$J$500,B42) -> 1
B49: Billing variance by client
B50: Client | C50: Variance ($)
B51: Kingsway Apparel | C51: =SUMIF(Billing!$B$2:$B$500,B51,Billing!$G$2:$G$500) -> 450
B52: Lakeshore Home Goods | C52: =SUMIF(Billing!$B$2:$B$500,B52,Billing!$G$2:$G$500) -> -140
B53: Northline Pet Supply | C53: =SUMIF(Billing!$B$2:$B$500,B53,Billing!$G$2:$G$500) -> 321.4
B54: Mimico Coffee Co. | C54: =SUMIF(Billing!$B$2:$B$500,B54,Billing!$G$2:$G$500) -> -117
B55: Total | C55: =SUM(C51:C54) -> 514.4

Sheet Inventory
A1: SKU | B1: Description | C1: System qty | D1: Physical count | E1: Variance | F1: Status | G1: Bin location | H1: Unit cost ($) | I1: Variance ($) | J1: Reason | K1: Count date
A2: KWA-10120 | B2: =IFERROR(INDEX(Items!$B$2:$B$200,MATCH($A2,Items!$A$2:$A$200,0)),"SKU not found") -> Crew neck tee, navy, M (case of 24) | C2: 14 | D2: 14 | E2: =D2-C2 -> 0 | F2: =IF(E2=0,"OK","Check") -> OK | G2: =IFERROR(INDEX(Items!$D$2:$D$200,MATCH($A2,Items!$A$2:$A$200,0)),"SKU not found") -> A-01-01 | H2: =IFERROR(INDEX(Items!$E$2:$E$200,MATCH($A2,Items!$A$2:$A$200,0)),0) -> 96 | I2: =E2*H2 -> 0 | K2: 46293
A3: KWA-10137 | B3: =IFERROR(INDEX(Items!$B$2:$B$200,MATCH($A3,Items!$A$2:$A$200,0)),"SKU not found") -> Crew neck tee, white, L (case of 24) | C3: 46 | D3: 46 | E3: =D3-C3 -> 0 | F3: =IF(E3=0,"OK","Check") -> OK | G3: =IFERROR(INDEX(Items!$D$2:$D$200,MATCH($A3,Items!$A$2:$A$200,0)),"SKU not found") -> A-01-02 | H3: =IFERROR(INDEX(Items!$E$2:$E$200,MATCH($A3,Items!$A$2:$A$200,0)),0) -> 96 | I3: =E3*H3 -> 0 | K3: 46293
A4: KWA-10154 | B4: =IFERROR(INDEX(Items!$B$2:$B$200,MATCH($A4,Items!$A$2:$A$200,0)),"SKU not found") -> Fleece hoodie, charcoal, M (case of 12) | C4: 52 | D4: 50 | E4: =D4-C4 -> -2 | F4: =IF(E4=0,"OK","Check") -> Check | G4: =IFERROR(INDEX(Items!$D$2:$D$200,MATCH($A4,Items!$A$2:$A$200,0)),"SKU not found") -> A-01-03 | H4: =IFERROR(INDEX(Items!$E$2:$E$200,MATCH($A4,Items!$A$2:$A$200,0)),0) -> 174 | I4: =E4*H4 -> -348 | J4: Mis-pick | K4: 46293
A5: KWA-10171 | B5: =IFERROR(INDEX(Items!$B$2:$B$200,MATCH($A5,Items!$A$2:$A$200,0)),"SKU not found") -> Fleece hoodie, charcoal, L (case of 12) | C5: 56 | D5: 56 | E5: =D5-C5 -> 0 | F5: =IF(E5=0,"OK","Check") -> OK | G5: =IFERROR(INDEX(Items!$D$2:$D$200,MATCH($A5,Items!$A$2:$A$200,0)),"SKU not found") -> A-02-01 | H5: =IFERROR(INDEX(Items!$E$2:$E$200,MATCH($A5,Items!$A$2:$A$200,0)),0) -> 174 | I5: =E5*H5 -> 0 | K5: 46293
A6: KWA-10188 | B6: =IFERROR(INDEX(Items!$B$2:$B$200,MATCH($A6,Items!$A$2:$A$200,0)),"SKU not found") -> Rain shell jacket, black, M (case of 6) | C6: 48 | D6: 48 | E6: =D6-C6 -> 0 | F6: =IF(E6=0,"OK","Check") -> OK | G6: =IFERROR(INDEX(Items!$D$2:$D$200,MATCH($A6,Items!$A$2:$A$200,0)),"SKU not found") -> A-02-02 | H6: =IFERROR(INDEX(Items!$E$2:$E$200,MATCH($A6,Items!$A$2:$A$200,0)),0) -> 207 | I6: =E6*H6 -> 0 | K6: 46293
A7: KWA-10205 | B7: =IFERROR(INDEX(Items!$B$2:$B$200,MATCH($A7,Items!$A$2:$A$200,0)),"SKU not found") -> Wool beanie, assorted (case of 36) | C7: 40 | D7: 40 | E7: =D7-C7 -> 0 | F7: =IF(E7=0,"OK","Check") -> OK | G7: =IFERROR(INDEX(Items!$D$2:$D$200,MATCH($A7,Items!$A$2:$A$200,0)),"SKU not found") -> A-02-03 | H7: =IFERROR(INDEX(Items!$E$2:$E$200,MATCH($A7,Items!$A$2:$A$200,0)),0) -> 118.8 | I7: =E7*H7 -> 0 | K7: 46293
A8: KWA-10222 | B8: =IFERROR(INDEX(Items!$B$2:$B$200,MATCH($A8,Items!$A$2:$A$200,0)),"SKU not found") -> Cargo pant, olive, 32x32 (case of 12) | C8: 22 | D8: 22 | E8: =D8-C8 -> 0 | F8: =IF(E8=0,"OK","Check") -> OK | G8: =IFERROR(INDEX(Items!$D$2:$D$200,MATCH($A8,Items!$A$2:$A$200,0)),"SKU not found") -> A-03-01 | H8: =IFERROR(INDEX(Items!$E$2:$E$200,MATCH($A8,Items!$A$2:$A$200,0)),0) -> 210 | I8: =E8*H8 -> 0 | K8: 46293
A9: KWA-10239 | B9: =IFERROR(INDEX(Items!$B$2:$B$200,MATCH($A9,Items!$A$2:$A$200,0)),"SKU not found") -> Athletic sock, 6 pk (case of 24) | C9: 24 | D9: 25 | E9: =D9-C9 -> 1 | F9: =IF(E9=0,"OK","Check") -> Check | G9: =IFERROR(INDEX(Items!$D$2:$D$200,MATCH($A9,Items!$A$2:$A$200,0)),"SKU not found") -> A-03-02 | H9: =IFERROR(INDEX(Items!$E$2:$E$200,MATCH($A9,Items!$A$2:$A$200,0)),0) -> 132 | I9: =E9*H9 -> 132 | J9: Receiving error | K9: 46293
A10: KWA-10256 | B10: =IFERROR(INDEX(Items!$B$2:$B$200,MATCH($A10,Items!$A$2:$A$200,0)),"SKU not found") -> Work glove, lined, L (case of 12) | C10: 54 | D10: 54 | E10: =D10-C10 -> 0 | F10: =IF(E10=0,"OK","Check") -> OK | G10: =IFERROR(INDEX(Items!$D$2:$D$200,MATCH($A10,Items!$A$2:$A$200,0)),"SKU not found") -> A-03-03 | H10: =IFERROR(INDEX(Items!$E$2:$E$200,MATCH($A10,Items!$A$2:$A$200,0)),0) -> 89.4 | I10: =E10*H10 -> 0 | K10: 46293
A11: KWA-10273 | B11: =IFERROR(INDEX(Items!$B$2:$B$200,MATCH($A11,Items!$A$2:$A$200,0)),"SKU not found") -> Zip fleece vest, navy, M (case of 12) | C11: 24 | D11: 24 | E11: =D11-C11 -> 0 | F11: =IF(E11=0,"OK","Check") -> OK | G11: =IFERROR(INDEX(Items!$D$2:$D$200,MATCH($A11,Items!$A$2:$A$200,0)),"SKU not found") -> A-04-01 | H11: =IFERROR(INDEX(Items!$E$2:$E$200,MATCH($A11,Items!$A$2:$A$200,0)),0) -> 156 | I11: =E11*H11 -> 0 | K11: 46293
A12: LHG-10123 | B12: =IFERROR(INDEX(Items!$B$2:$B$200,MATCH($A12,Items!$A$2:$A$200,0)),"SKU not found") -> Stoneware dinner plate, set of 4 | C12: 26 | D12: 26 | E12: =D12-C12 -> 0 | F12: =IF(E12=0,"OK","Check") -> OK | G12: =IFERROR(INDEX(Items!$D$2:$D$200,MATCH($A12,Items!$A$2:$A$200,0)),"SKU not found") -> B-01-01 | H12: =IFERROR(INDEX(Items!$E$2:$E$200,MATCH($A12,Items!$A$2:$A$200,0)),0) -> 21.8 | I12: =E12*H12 -> 0 | K12: 46293
A13: LHG-10140 | B13: =IFERROR(INDEX(Items!$B$2:$B$200,MATCH($A13,Items!$A$2:$A$200,0)),"SKU not found") -> Glass tumbler, 12 oz, set of 6 | C13: 135 | D13: 134 | E13: =D13-C13 -> -1 | F13: =IF(E13=0,"OK","Check") -> Check | G13: =IFERROR(INDEX(Items!$D$2:$D$200,MATCH($A13,Items!$A$2:$A$200,0)),"SKU not found") -> B-01-02 | H13: =IFERROR(INDEX(Items!$E$2:$E$200,MATCH($A13,Items!$A$2:$A$200,0)),0) -> 14.25 | I13: =E13*H13 -> -14.25 | J13: Damaged, not recorded | K13: 46293
A14: LHG-10157 | B14: =IFERROR(INDEX(Items!$B$2:$B$200,MATCH($A14,Items!$A$2:$A$200,0)),"SKU not found") -> Cotton bath towel, grey | C14: 30 | D14: 30 | E14: =D14-C14 -> 0 | F14: =IF(E14=0,"OK","Check") -> OK | G14: =IFERROR(INDEX(Items!$D$2:$D$200,MATCH($A14,Items!$A$2:$A$200,0)),"SKU not found") -> B-01-03 | H14: =IFERROR(INDEX(Items!$E$2:$E$200,MATCH($A14,Items!$A$2:$A$200,0)),0) -> 9.6 | I14: =E14*H14 -> 0 | K14: 46293
A15: LHG-10174 | B15: =IFERROR(INDEX(Items!$B$2:$B$200,MATCH($A15,Items!$A$2:$A$200,0)),"SKU not found") -> Queen sheet set, white | C15: 50 | D15: 50 | E15: =D15-C15 -> 0 | F15: =IF(E15=0,"OK","Check") -> OK | G15: =IFERROR(INDEX(Items!$D$2:$D$200,MATCH($A15,Items!$A$2:$A$200,0)),"SKU not found") -> B-02-01 | H15: =IFERROR(INDEX(Items!$E$2:$E$200,MATCH($A15,Items!$A$2:$A$200,0)),0) -> 31.4 | I15: =E15*H15 -> 0 | K15: 46293
A16: LHG-10191 | B16: =IFERROR(INDEX(Items!$B$2:$B$200,MATCH($A16,Items!$A$2:$A$200,0)),"SKU not found") -> Non-stick fry pan, 10 in | C16: 36 | D16: 36 | E16: =D16-C16 -> 0 | F16: =IF(E16=0,"OK","Check") -> OK | G16: =IFERROR(INDEX(Items!$D$2:$D$200,MATCH($A16,Items!$A$2:$A$200,0)),"SKU not found") -> B-02-02 | H16: =IFERROR(INDEX(Items!$E$2:$E$200,MATCH($A16,Items!$A$2:$A$200,0)),0) -> 17.9 | I16: =E16*H16 -> 0 | K16: 46294
A17: LHG-10208 | B17: =IFERROR(INDEX(Items!$B$2:$B$200,MATCH($A17,Items!$A$2:$A$200,0)),"SKU not found") -> Ceramic table lamp, 24 in | C17: 26 | D17: 26 | E17: =D17-C17 -> 0 | F17: =IF(E17=0,"OK","Check") -> OK | G17: =IFERROR(INDEX(Items!$D$2:$D$200,MATCH($A17,Items!$A$2:$A$200,0)),"SKU not found") -> B-02-03 | H17: =IFERROR(INDEX(Items!$E$2:$E$200,MATCH($A17,Items!$A$2:$A$200,0)),0) -> 38.5 | I17: =E17*H17 -> 0 | K17: 46294
A18: LHG-10225 | B18: =IFERROR(INDEX(Items!$B$2:$B$200,MATCH($A18,Items!$A$2:$A$200,0)),"SKU not found") -> Throw pillow cover, linen, 18 in | C18: 90 | D18: 87 | E18: =D18-C18 -> -3 | F18: =IF(E18=0,"OK","Check") -> Check | G18: =IFERROR(INDEX(Items!$D$2:$D$200,MATCH($A18,Items!$A$2:$A$200,0)),"SKU not found") -> B-03-01 | H18: =IFERROR(INDEX(Items!$E$2:$E$200,MATCH($A18,Items!$A$2:$A$200,0)),0) -> 6.75 | I18: =E18*H18 -> -20.25 | J18: Unrecorded transfer | K18: 46294
A19: LHG-10242 | B19: =IFERROR(INDEX(Items!$B$2:$B$200,MATCH($A19,Items!$A$2:$A$200,0)),"SKU not found") -> Bamboo cutting board, large | C19: 125 | D19: 125 | E19: =D19-C19 -> 0 | F19: =IF(E19=0,"OK","Check") -> OK | G19: =IFERROR(INDEX(Items!$D$2:$D$200,MATCH($A19,Items!$A$2:$A$200,0)),"SKU not found") -> B-03-02 | H19: =IFERROR(INDEX(Items!$E$2:$E$200,MATCH($A19,Items!$A$2:$A$200,0)),0) -> 11.2 | I19: =E19*H19 -> 0 | K19: 46294
A20: LHG-10259 | B20: =IFERROR(INDEX(Items!$B$2:$B$200,MATCH($A20,Items!$A$2:$A$200,0)),"SKU not found") -> Wall clock, 12 in, black | C20: 80 | D20: 80 | E20: =D20-C20 -> 0 | F20: =IF(E20=0,"OK","Check") -> OK | G20: =IFERROR(INDEX(Items!$D$2:$D$200,MATCH($A20,Items!$A$2:$A$200,0)),"SKU not found") -> B-03-03 | H20: =IFERROR(INDEX(Items!$E$2:$E$200,MATCH($A20,Items!$A$2:$A$200,0)),0) -> 13.8 | I20: =E20*H20 -> 0 | K20: 46294
A21: LHG-10276 | B21: =IFERROR(INDEX(Items!$B$2:$B$200,MATCH($A21,Items!$A$2:$A$200,0)),"SKU not found") -> Storage bin, woven, set of 3 | C21: 32 | D21: 32 | E21: =D21-C21 -> 0 | F21: =IF(E21=0,"OK","Check") -> OK | G21: =IFERROR(INDEX(Items!$D$2:$D$200,MATCH($A21,Items!$A$2:$A$200,0)),"SKU not found") -> B-04-01 | H21: =IFERROR(INDEX(Items!$E$2:$E$200,MATCH($A21,Items!$A$2:$A$200,0)),0) -> 19.95 | I21: =E21*H21 -> 0 | K21: 46294
A22: NPS-10126 | B22: =IFERROR(INDEX(Items!$B$2:$B$200,MATCH($A22,Items!$A$2:$A$200,0)),"SKU not found") -> Dry dog food, adult, 13.6 kg | C22: 56 | D22: 56 | E22: =D22-C22 -> 0 | F22: =IF(E22=0,"OK","Check") -> OK | G22: =IFERROR(INDEX(Items!$D$2:$D$200,MATCH($A22,Items!$A$2:$A$200,0)),"SKU not found") -> C-01-01 | H22: =IFERROR(INDEX(Items!$E$2:$E$200,MATCH($A22,Items!$A$2:$A$200,0)),0) -> 41.2 | I22: =E22*H22 -> 0 | K22: 46294
A23: NPS-10143 | B23: =IFERROR(INDEX(Items!$B$2:$B$200,MATCH($A23,Items!$A$2:$A$200,0)),"SKU not found") -> Dry cat food, indoor, 7 kg | C23: 14 | D23: 13 | E23: =D23-C23 -> -1 | F23: =IF(E23=0,"OK","Check") -> Check | G23: =IFERROR(INDEX(Items!$D$2:$D$200,MATCH($A23,Items!$A$2:$A$200,0)),"SKU not found") -> C-01-02 | H23: =IFERROR(INDEX(Items!$E$2:$E$200,MATCH($A23,Items!$A$2:$A$200,0)),0) -> 28.9 | I23: =E23*H23 -> -28.9 | J23: Mis-pick | K23: 46294
A24: NPS-10160 | B24: =IFERROR(INDEX(Items!$B$2:$B$200,MATCH($A24,Items!$A$2:$A$200,0)),"SKU not found") -> Clumping cat litter, 18 kg | C24: 60 | D24: 60 | E24: =D24-C24 -> 0 | F24: =IF(E24=0,"OK","Check") -> OK | G24: =IFERROR(INDEX(Items!$D$2:$D$200,MATCH($A24,Items!$A$2:$A$200,0)),"SKU not found") -> C-01-03 | H24: =IFERROR(INDEX(Items!$E$2:$E$200,MATCH($A24,Items!$A$2:$A$200,0)),0) -> 12.4 | I24: =E24*H24 -> 0 | K24: 46294
A25: NPS-10177 | B25: =IFERROR(INDEX(Items!$B$2:$B$200,MATCH($A25,Items!$A$2:$A$200,0)),"SKU not found") -> Dog leash, nylon, 6 ft | C25: 55 | D25: 55 | E25: =D25-C25 -> 0 | F25: =IF(E25=0,"OK","Check") -> OK | G25: =IFERROR(INDEX(Items!$D$2:$D$200,MATCH($A25,Items!$A$2:$A$200,0)),"SKU not found") -> C-02-01 | H25: =IFERROR(INDEX(Items!$E$2:$E$200,MATCH($A25,Items!$A$2:$A$200,0)),0) -> 5.85 | I25: =E25*H25 -> 0 | K25: 46294
A26: NPS-10194 | B26: =IFERROR(INDEX(Items!$B$2:$B$200,MATCH($A26,Items!$A$2:$A$200,0)),"SKU not found") -> Rawhide-free chew, 10 pk | C26: 70 | D26: 72 | E26: =D26-C26 -> 2 | F26: =IF(E26=0,"OK","Check") -> Check | G26: =IFERROR(INDEX(Items!$D$2:$D$200,MATCH($A26,Items!$A$2:$A$200,0)),"SKU not found") -> C-02-02 | H26: =IFERROR(INDEX(Items!$E$2:$E$200,MATCH($A26,Items!$A$2:$A$200,0)),0) -> 8.7 | I26: =E26*H26 -> 17.4 | J26: Count error | K26: 46294
A27: NPS-10211 | B27: =IFERROR(INDEX(Items!$B$2:$B$200,MATCH($A27,Items!$A$2:$A$200,0)),"SKU not found") -> Stainless dog bowl, large | C27: 75 | D27: 75 | E27: =D27-C27 -> 0 | F27: =IF(E27=0,"OK","Check") -> OK | G27: =IFERROR(INDEX(Items!$D$2:$D$200,MATCH($A27,Items!$A$2:$A$200,0)),"SKU not found") -> C-02-03 | H27: =IFERROR(INDEX(Items!$E$2:$E$200,MATCH($A27,Items!$A$2:$A$200,0)),0) -> 6.1 | I27: =E27*H27 -> 0 | K27: 46294
A28: NPS-10228 | B28: =IFERROR(INDEX(Items!$B$2:$B$200,MATCH($A28,Items!$A$2:$A$200,0)),"SKU not found") -> Cat scratching post, 32 in | C28: 58 | D28: 58 | E28: =D28-C28 -> 0 | F28: =IF(E28=0,"OK","Check") -> OK | G28: =IFERROR(INDEX(Items!$D$2:$D$200,MATCH($A28,Items!$A$2:$A$200,0)),"SKU not found") -> C-03-01 | H28: =IFERROR(INDEX(Items!$E$2:$E$200,MATCH($A28,Items!$A$2:$A$200,0)),0) -> 22.6 | I28: =E28*H28 -> 0 | K28: 46294
A29: NPS-10245 | B29: =IFERROR(INDEX(Items!$B$2:$B$200,MATCH($A29,Items!$A$2:$A$200,0)),"SKU not found") -> Puppy training pads, 100 ct | C29: 24 | D29: 24 | E29: =D29-C29 -> 0 | F29: =IF(E29=0,"OK","Check") -> OK | G29: =IFERROR(INDEX(Items!$D$2:$D$200,MATCH($A29,Items!$A$2:$A$200,0)),"SKU not found") -> C-03-02 | H29: =IFERROR(INDEX(Items!$E$2:$E$200,MATCH($A29,Items!$A$2:$A$200,0)),0) -> 18.3 | I29: =E29*H29 -> 0 | K29: 46294
A30: NPS-10262 | B30: =IFERROR(INDEX(Items!$B$2:$B$200,MATCH($A30,Items!$A$2:$A$200,0)),"SKU not found") -> Dog bed, orthopedic, medium | C30: 30 | D30: 24 | E30: =D30-C30 -> -6 | F30: =IF(E30=0,"OK","Check") -> Check | G30: =IFERROR(INDEX(Items!$D$2:$D$200,MATCH($A30,Items!$A$2:$A$200,0)),"SKU not found") -> C-03-03 | H30: =IFERROR(INDEX(Items!$E$2:$E$200,MATCH($A30,Items!$A$2:$A$200,0)),0) -> 34.75 | I30: =E30*H30 -> -208.5 | J30: Receiving error | K30: 46295
A31: NPS-10279 | B31: =IFERROR(INDEX(Items!$B$2:$B$200,MATCH($A31,Items!$A$2:$A$200,0)),"SKU not found") -> Bird seed mix, 4.5 kg | C31: 145 | D31: 145 | E31: =D31-C31 -> 0 | F31: =IF(E31=0,"OK","Check") -> OK | G31: =IFERROR(INDEX(Items!$D$2:$D$200,MATCH($A31,Items!$A$2:$A$200,0)),"SKU not found") -> C-04-01 | H31: =IFERROR(INDEX(Items!$E$2:$E$200,MATCH($A31,Items!$A$2:$A$200,0)),0) -> 9.95 | I31: =E31*H31 -> 0 | K31: 46295
A32: MCC-10129 | B32: =IFERROR(INDEX(Items!$B$2:$B$200,MATCH($A32,Items!$A$2:$A$200,0)),"SKU not found") -> Whole bean, house blend, 1 kg | C32: 48 | D32: 48 | E32: =D32-C32 -> 0 | F32: =IF(E32=0,"OK","Check") -> OK | G32: =IFERROR(INDEX(Items!$D$2:$D$200,MATCH($A32,Items!$A$2:$A$200,0)),"SKU not found") -> D-01-01 | H32: =IFERROR(INDEX(Items!$E$2:$E$200,MATCH($A32,Items!$A$2:$A$200,0)),0) -> 17.4 | I32: =E32*H32 -> 0 | K32: 46295
A33: MCC-10146 | B33: =IFERROR(INDEX(Items!$B$2:$B$200,MATCH($A33,Items!$A$2:$A$200,0)),"SKU not found") -> Whole bean, dark roast, 1 kg | C33: 48 | D33: 48 | E33: =D33-C33 -> 0 | F33: =IF(E33=0,"OK","Check") -> OK | G33: =IFERROR(INDEX(Items!$D$2:$D$200,MATCH($A33,Items!$A$2:$A$200,0)),"SKU not found") -> D-01-02 | H33: =IFERROR(INDEX(Items!$E$2:$E$200,MATCH($A33,Items!$A$2:$A$200,0)),0) -> 18.1 | I33: =E33*H33 -> 0 | K33: 46295
A34: MCC-10163 | B34: =IFERROR(INDEX(Items!$B$2:$B$200,MATCH($A34,Items!$A$2:$A$200,0)),"SKU not found") -> Ground, medium roast, 340 g | C34: 100 | D34: 100 | E34: =D34-C34 -> 0 | F34: =IF(E34=0,"OK","Check") -> OK | G34: =IFERROR(INDEX(Items!$D$2:$D$200,MATCH($A34,Items!$A$2:$A$200,0)),"SKU not found") -> D-01-03 | H34: =IFERROR(INDEX(Items!$E$2:$E$200,MATCH($A34,Items!$A$2:$A$200,0)),0) -> 6.95 | I34: =E34*H34 -> 0 | K34: 46295
A35: MCC-10180 | B35: =IFERROR(INDEX(Items!$B$2:$B$200,MATCH($A35,Items!$A$2:$A$200,0)),"SKU not found") -> Decaf whole bean, 1 kg | C35: 16 | D35: 15 | E35: =D35-C35 -> -1 | F35: =IF(E35=0,"OK","Check") -> Check | G35: =IFERROR(INDEX(Items!$D$2:$D$200,MATCH($A35,Items!$A$2:$A$200,0)),"SKU not found") -> D-02-01 | H35: =IFERROR(INDEX(Items!$E$2:$E$200,MATCH($A35,Items!$A$2:$A$200,0)),0) -> 19.2 | I35: =E35*H35 -> -19.2 | J35: Damaged, not recorded | K35: 46295
A36: MCC-10197 | B36: =IFERROR(INDEX(Items!$B$2:$B$200,MATCH($A36,Items!$A$2:$A$200,0)),"SKU not found") -> Paper cup, 12 oz (sleeve of 50) | C36: 45 | D36: 45 | E36: =D36-C36 -> 0 | F36: =IF(E36=0,"OK","Check") -> OK | G36: =IFERROR(INDEX(Items!$D$2:$D$200,MATCH($A36,Items!$A$2:$A$200,0)),"SKU not found") -> D-02-02 | H36: =IFERROR(INDEX(Items!$E$2:$E$200,MATCH($A36,Items!$A$2:$A$200,0)),0) -> 4.6 | I36: =E36*H36 -> 0 | K36: 46295
A37: MCC-10214 | B37: =IFERROR(INDEX(Items!$B$2:$B$200,MATCH($A37,Items!$A$2:$A$200,0)),"SKU not found") -> Cup lid, 12 oz (sleeve of 100) | C37: 105 | D37: 105 | E37: =D37-C37 -> 0 | F37: =IF(E37=0,"OK","Check") -> OK | G37: =IFERROR(INDEX(Items!$D$2:$D$200,MATCH($A37,Items!$A$2:$A$200,0)),"SKU not found") -> D-02-03 | H37: =IFERROR(INDEX(Items!$E$2:$E$200,MATCH($A37,Items!$A$2:$A$200,0)),0) -> 3.9 | I37: =E37*H37 -> 0 | K37: 46295
A38: MCC-10231 | B38: =IFERROR(INDEX(Items!$B$2:$B$200,MATCH($A38,Items!$A$2:$A$200,0)),"SKU not found") -> Cold brew pack, 6 x 355 ml | C38: 125 | D38: 125 | E38: =D38-C38 -> 0 | F38: =IF(E38=0,"OK","Check") -> OK | G38: =IFERROR(INDEX(Items!$D$2:$D$200,MATCH($A38,Items!$A$2:$A$200,0)),"SKU not found") -> D-03-01 | H38: =IFERROR(INDEX(Items!$E$2:$E$200,MATCH($A38,Items!$A$2:$A$200,0)),0) -> 11.8 | I38: =E38*H38 -> 0 | K38: 46295
A39: MCC-10248 | B39: =IFERROR(INDEX(Items!$B$2:$B$200,MATCH($A39,Items!$A$2:$A$200,0)),"SKU not found") -> Pour-over filters, 100 ct | C39: 125 | D39: 121 | E39: =D39-C39 -> -4 | F39: =IF(E39=0,"OK","Check") -> Check | G39: =IFERROR(INDEX(Items!$D$2:$D$200,MATCH($A39,Items!$A$2:$A$200,0)),"SKU not found") -> D-03-02 | H39: =IFERROR(INDEX(Items!$E$2:$E$200,MATCH($A39,Items!$A$2:$A$200,0)),0) -> 3.25 | I39: =E39*H39 -> -13 | J39: Theft or loss | K39: 46295
A40: MCC-10265 | B40: =IFERROR(INDEX(Items!$B$2:$B$200,MATCH($A40,Items!$A$2:$A$200,0)),"SKU not found") -> Espresso pods, 50 ct | C40: 24 | D40: 24 | E40: =D40-C40 -> 0 | F40: =IF(E40=0,"OK","Check") -> OK | G40: =IFERROR(INDEX(Items!$D$2:$D$200,MATCH($A40,Items!$A$2:$A$200,0)),"SKU not found") -> D-03-03 | H40: =IFERROR(INDEX(Items!$E$2:$E$200,MATCH($A40,Items!$A$2:$A$200,0)),0) -> 21.5 | I40: =E40*H40 -> 0 | K40: 46295
...

Sheet Receiving
A1: Receipt date | B1: PO | C1: Carrier | D1: BOL | E1: SKU | F1: Description | G1: PO qty | H1: Packing slip qty | I1: Qty received | J1: Variance | K1: Flag | L1: Week
A2: 46266 | B2: PO 48210 | C2: Purolator Freight | D2: 3723718 | E2: KWA-10188 | F2: =IFERROR(INDEX(Items!$B$2:$B$200,MATCH($E2,Items!$A$2:$A$200,0)),"SKU not found") -> Rain shell jacket, black, M (case of 6) | G2: 56 | H2: 56 | I2: 56 | J2: =I2-H2 -> 0 | K2: =IF(J2<0,"Short",IF(J2>0,"Over",IF(H2<>G2,"PO mismatch","OK"))) -> OK | L2: ="Wk "&TEXT(WEEKNUM(A2,2),"00") -> Wk 36
A3: 46266 | B3: PO 48210 | C3: Purolator Freight | D3: 3387367 | E3: KWA-10137 | F3: =IFERROR(INDEX(Items!$B$2:$B$200,MATCH($E3,Items!$A$2:$A$200,0)),"SKU not found") -> Crew neck tee, white, L (case of 24) | G3: 40 | H3: 40 | I3: 40 | J3: =I3-H3 -> 0 | K3: =IF(J3<0,"Short",IF(J3>0,"Over",IF(H3<>G3,"PO mismatch","OK"))) -> OK | L3: ="Wk "&TEXT(WEEKNUM(A3,2),"00") -> Wk 36
A4: 46267 | B4: PO 48219 | C4: UPS Freight | D4: 3559955 | E4: NPS-10211 | F4: =IFERROR(INDEX(Items!$B$2:$B$200,MATCH($E4,Items!$A$2:$A$200,0)),"SKU not found") -> Stainless dog bowl, large | G4: 230 | H4: 230 | I4: 230 | J4: =I4-H4 -> 0 | K4: =IF(J4<0,"Short",IF(J4>0,"Over",IF(H4<>G4,"PO mismatch","OK"))) -> OK | L4: ="Wk "&TEXT(WEEKNUM(A4,2),"00") -> Wk 36
A5: 46267 | B5: PO 48219 | C5: Purolator Freight | D5: 3706895 | E5: KWA-10222 | F5: =IFERROR(INDEX(Items!$B$2:$B$200,MATCH($E5,Items!$A$2:$A$200,0)),"SKU not found") -> Cargo pant, olive, 32x32 (case of 12) | G5: 88 | H5: 88 | I5: 86 | J5: =I5-H5 -> -2 | K5: =IF(J5<0,"Short",IF(J5>0,"Over",IF(H5<>G5,"PO mismatch","OK"))) -> Short | L5: ="Wk "&TEXT(WEEKNUM(A5,2),"00") -> Wk 36
A6: 46268 | B6: PO 48227 | C6: Purolator Freight | D6: 3883290 | E6: LHG-10140 | F6: =IFERROR(INDEX(Items!$B$2:$B$200,MATCH($E6,Items!$A$2:$A$200,0)),"SKU not found") -> Glass tumbler, 12 oz, set of 6 | G6: 190 | H6: 190 | I6: 190 | J6: =I6-H6 -> 0 | K6: =IF(J6<0,"Short",IF(J6>0,"Over",IF(H6<>G6,"PO mismatch","OK"))) -> OK | L6: ="Wk "&TEXT(WEEKNUM(A6,2),"00") -> Wk 36
A7: 46268 | B7: PO 48227 | C7: Day & Ross | D7: 3383986 | E7: MCC-10163 | F7: =IFERROR(INDEX(Items!$B$2:$B$200,MATCH($E7,Items!$A$2:$A$200,0)),"SKU not found") -> Ground, medium roast, 340 g | G7: 180 | H7: 180 | I7: 180 | J7: =I7-H7 -> 0 | K7: =IF(J7<0,"Short",IF(J7>0,"Over",IF(H7<>G7,"PO mismatch","OK"))) -> OK | L7: ="Wk "&TEXT(WEEKNUM(A7,2),"00") -> Wk 36
A8: 46269 | B8: PO 48233 | C8: Manitoulin Transport | D8: 3624791 | E8: MCC-10146 | F8: =IFERROR(INDEX(Items!$B$2:$B$200,MATCH($E8,Items!$A$2:$A$200,0)),"SKU not found") -> Whole bean, dark roast, 1 kg | G8: 48 | H8: 48 | I8: 48 | J8: =I8-H8 -> 0 | K8: =IF(J8<0,"Short",IF(J8>0,"Over",IF(H8<>G8,"PO mismatch","OK"))) -> OK | L8: ="Wk "&TEXT(WEEKNUM(A8,2),"00") -> Wk 36
A9: 46269 | B9: PO 48237 | C9: Purolator Freight | D9: 3392166 | E9: KWA-10239 | F9: =IFERROR(INDEX(Items!$B$2:$B$200,MATCH($E9,Items!$A$2:$A$200,0)),"SKU not found") -> Athletic sock, 6 pk (case of 24) | G9: 48 | H9: 48 | I9: 48 | J9: =I9-H9 -> 0 | K9: =IF(J9<0,"Short",IF(J9>0,"Over",IF(H9<>G9,"PO mismatch","OK"))) -> OK | L9: ="Wk "&TEXT(WEEKNUM(A9,2),"00") -> Wk 36
A10: 46272 | B10: PO 48241 | C10: Day & Ross | D10: 3876304 | E10: KWA-10137 | F10: =IFERROR(INDEX(Items!$B$2:$B$200,MATCH($E10,Items!$A$2:$A$200,0)),"SKU not found") -> Crew neck tee, white, L (case of 24) | G10: 68 | H10: 68 | I10: 68 | J10: =I10-H10 -> 0 | K10: =IF(J10<0,"Short",IF(J10>0,"Over",IF(H10<>G10,"PO mismatch","OK"))) -> OK | L10: ="Wk "&TEXT(WEEKNUM(A10,2),"00") -> Wk 37
A11: 46272 | B11: PO 48241 | C11: UPS Freight | D11: 3714406 | E11: KWA-10239 | F11: =IFERROR(INDEX(Items!$B$2:$B$200,MATCH($E11,Items!$A$2:$A$200,0)),"SKU not found") -> Athletic sock, 6 pk (case of 24) | G11: 24 | H11: 24 | I11: 25 | J11: =I11-H11 -> 1 | K11: =IF(J11<0,"Short",IF(J11>0,"Over",IF(H11<>G11,"PO mismatch","OK"))) -> Over | L11: ="Wk "&TEXT(WEEKNUM(A11,2),"00") -> Wk 37
A12: 46273 | B12: PO 48250 | C12: Day & Ross | D12: 3660831 | E12: MCC-10129 | F12: =IFERROR(INDEX(Items!$B$2:$B$200,MATCH($E12,Items!$A$2:$A$200,0)),"SKU not found") -> Whole bean, house blend, 1 kg | G12: 64 | H12: 64 | I12: 64 | J12: =I12-H12 -> 0 | K12: =IF(J12<0,"Short",IF(J12>0,"Over",IF(H12<>G12,"PO mismatch","OK"))) -> OK | L12: ="Wk "&TEXT(WEEKNUM(A12,2),"00") -> Wk 37
A13: 46273 | B13: PO 48250 | C13: Manitoulin Transport | D13: 3608424 | E13: NPS-10279 | F13: =IFERROR(INDEX(Items!$B$2:$B$200,MATCH($E13,Items!$A$2:$A$200,0)),"SKU not found") -> Bird seed mix, 4.5 kg | G13: 180 | H13: 180 | I13: 180 | J13: =I13-H13 -> 0 | K13: =IF(J13<0,"Short",IF(J13>0,"Over",IF(H13<>G13,"PO mismatch","OK"))) -> OK | L13: ="Wk "&TEXT(WEEKNUM(A13,2),"00") -> Wk 37
... A41: 46293 | B41: PO 48361 | C41: UPS Freight | D41: 3837371 | E41: MCC-10265 | F41: =IFERROR(INDEX(Items!$B$2:$B$200,MATCH($E41,Items!$A$2:$A$200,0)),"SKU not found") -> Espresso pods, 50 ct | G41: 20 | H41: 20 | I41: 20 | J41: =I41-H41 -> 0 | K41: =IF(J41<0,"Short",IF(J41>0,"Over",IF(H41<>G41,"PO mismatch","OK"))) -> OK | L41: ="Wk "&TEXT(WEEKNUM(A41,2),"00") -> Wk 40

Sheet Billing
A1: Month | B1: Client | C1: Pallets stored | D1: Rate ($) | E1: Invoice amount ($) | F1: Expected ($) | G1: Variance ($) | H1: Flag
A2: 46023 | B2: Kingsway Apparel | C2: 147 | D2: =IFERROR(INDEX(Lists!$F$2:$F$20,MATCH(B2,Lists!$E$2:$E$20,0)),0) -> 24.5 | E2: 3601.5 | F2: =C2*D2 -> 3601.5 | G2: =E2-F2 -> 0 | H2: =IF(ABS(G2)>Lists!$I$2,"Check","OK") -> OK
A3: 46023 | B3: Lakeshore Home Goods | C3: 96 | D3: =IFERROR(INDEX(Lists!$F$2:$F$20,MATCH(B3,Lists!$E$2:$E$20,0)),0) -> 22 | E3: 2112 | F3: =C3*D3 -> 2112 | G3: =E3-F3 -> 0 | H3: =IF(ABS(G3)>Lists!$I$2,"Check","OK") -> OK
A4: 46023 | B4: Northline Pet Supply | C4: 189 | D4: =IFERROR(INDEX(Lists!$F$2:$F$20,MATCH(B4,Lists!$E$2:$E$20,0)),0) -> 26.75 | E4: 5055.75 | F4: =C4*D4 -> 5055.75 | G4: =E4-F4 -> 0 | H4: =IF(ABS(G4)>Lists!$I$2,"Check","OK") -> OK
A5: 46023 | B5: Mimico Coffee Co. | C5: 59 | D5: =IFERROR(INDEX(Lists!$F$2:$F$20,MATCH(B5,Lists!$E$2:$E$20,0)),0) -> 19.5 | E5: 1150.5 | F5: =C5*D5 -> 1150.5 | G5: =E5-F5 -> 0 | H5: =IF(ABS(G5)>Lists!$I$2,"Check","OK") -> OK
A6: 46054 | B6: Kingsway Apparel | C6: 160 | D6: =IFERROR(INDEX(Lists!$F$2:$F$20,MATCH(B6,Lists!$E$2:$E$20,0)),0) -> 24.5 | E6: 3920 | F6: =C6*D6 -> 3920 | G6: =E6-F6 -> 0 | H6: =IF(ABS(G6)>Lists!$I$2,"Check","OK") -> OK
A7: 46054 | B7: Lakeshore Home Goods | C7: 99 | D7: =IFERROR(INDEX(Lists!$F$2:$F$20,MATCH(B7,Lists!$E$2:$E$20,0)),0) -> 22 | E7: 2178 | F7: =C7*D7 -> 2178 | G7: =E7-F7 -> 0 | H7: =IF(ABS(G7)>Lists!$I$2,"Check","OK") -> OK
A8: 46054 | B8: Northline Pet Supply | C8: 186 | D8: =IFERROR(INDEX(Lists!$F$2:$F$20,MATCH(B8,Lists!$E$2:$E$20,0)),0) -> 26.75 | E8: 4975.5 | F8: =C8*D8 -> 4975.5 | G8: =E8-F8 -> 0 | H8: =IF(ABS(G8)>Lists!$I$2,"Check","OK") -> OK
A9: 46054 | B9: Mimico Coffee Co. | C9: 81 | D9: =IFERROR(INDEX(Lists!$F$2:$F$20,MATCH(B9,Lists!$E$2:$E$20,0)),0) -> 19.5 | E9: 1579.5 | F9: =C9*D9 -> 1579.5 | G9: =E9-F9 -> 0 | H9: =IF(ABS(G9)>Lists!$I$2,"Check","OK") -> OK
A10: 46082 | B10: Kingsway Apparel | C10: 133 | D10: =IFERROR(INDEX(Lists!$F$2:$F$20,MATCH(B10,Lists!$E$2:$E$20,0)),0) -> 24.5 | E10: 3258.5 | F10: =C10*D10 -> 3258.5 | G10: =E10-F10 -> 0 | H10: =IF(ABS(G10)>Lists!$I$2,"Check","OK") -> OK
A11: 46082 | B11: Lakeshore Home Goods | C11: 112 | D11: =IFERROR(INDEX(Lists!$F$2:$F$20,MATCH(B11,Lists!$E$2:$E$20,0)),0) -> 22 | E11: 2324 | F11: =C11*D11 -> 2464 | G11: =E11-F11 -> -140 | H11: =IF(ABS(G11)>Lists!$I$2,"Check","OK") -> Check
A12: 46082 | B12: Northline Pet Supply | C12: 188 | D12: =IFERROR(INDEX(Lists!$F$2:$F$20,MATCH(B12,Lists!$E$2:$E$20,0)),0) -> 26.75 | E12: 5029 | F12: =C12*D12 -> 5029 | G12: =E12-F12 -> 0 | H12: =IF(ABS(G12)>Lists!$I$2,"Check","OK") -> OK
A13: 46082 | B13: Mimico Coffee Co. | C13: 54 | D13: =IFERROR(INDEX(Lists!$F$2:$F$20,MATCH(B13,Lists!$E$2:$E$20,0)),0) -> 19.5 | E13: 1053 | F13: =C13*D13 -> 1053 | G13: =E13-F13 -> 0 | H13: =IF(ABS(G13)>Lists!$I$2,"Check","OK") -> OK
... A37: 46266 | B37: Mimico Coffee Co. | C37: 68 | D37: =IFERROR(INDEX(Lists!$F$2:$F$20,MATCH(B37,Lists!$E$2:$E$20,0)),0) -> 19.5 | E37: 1326 | F37: =C37*D37 -> 1326 | G37: =E37-F37 -> 0 | H37: =IF(ABS(G37)>Lists!$I$2,"Check","OK") -> OK
F39: Total variance | G39: =SUM(G2:G37) -> 514.4

Sheet Items
A1: SKU | B1: Description | C1: Client | D1: Bin location | E1: Unit cost ($)
A2: KWA-10120 | B2: Crew neck tee, navy, M (case of 24) | C2: Kingsway Apparel | D2: A-01-01 | E2: 96
A3: KWA-10137 | B3: Crew neck tee, white, L (case of 24) | C3: Kingsway Apparel | D3: A-01-02 | E3: 96
A4: KWA-10154 | B4: Fleece hoodie, charcoal, M (case of 12) | C4: Kingsway Apparel | D4: A-01-03 | E4: 174
A5: KWA-10171 | B5: Fleece hoodie, charcoal, L (case of 12) | C5: Kingsway Apparel | D5: A-02-01 | E5: 174
A6: KWA-10188 | B6: Rain shell jacket, black, M (case of 6) | C6: Kingsway Apparel | D6: A-02-02 | E6: 207
A7: KWA-10205 | B7: Wool beanie, assorted (case of 36) | C7: Kingsway Apparel | D7: A-02-03 | E7: 118.8
A8: KWA-10222 | B8: Cargo pant, olive, 32x32 (case of 12) | C8: Kingsway Apparel | D8: A-03-01 | E8: 210
A9: KWA-10239 | B9: Athletic sock, 6 pk (case of 24) | C9: Kingsway Apparel | D9: A-03-02 | E9: 132
A10: KWA-10256 | B10: Work glove, lined, L (case of 12) | C10: Kingsway Apparel | D10: A-03-03 | E10: 89.4
A11: KWA-10273 | B11: Zip fleece vest, navy, M (case of 12) | C11: Kingsway Apparel | D11: A-04-01 | E11: 156
A12: LHG-10123 | B12: Stoneware dinner plate, set of 4 | C12: Lakeshore Home Goods | D12: B-01-01 | E12: 21.8
A13: LHG-10140 | B13: Glass tumbler, 12 oz, set of 6 | C13: Lakeshore Home Goods | D13: B-01-02 | E13: 14.25
... A41: MCC-10282 | B41: Travel mug, 16 oz, steel | C41: Mimico Coffee Co. | D41: D-04-01 | E41: 9.4

Sheet Lists
A1: Reason codes | C1: Carriers | E1: Client | F1: Storage rate ($ per pallet per month) | H1: Setting | I1: Value
A2: Count error | C2: Purolator Freight | E2: Kingsway Apparel | F2: 24.5 | H2: Billing tolerance ($) | I2: 1
A3: Mis-pick | C3: Day & Ross | E3: Lakeshore Home Goods | F3: 22 | H3: Invoices more than this away from expected are flagged.
A4: Receiving error | C4: Manitoulin Transport | E4: Northline Pet Supply | F4: 26.75
A5: Damaged, not recorded | C5: Canpar | E5: Mimico Coffee Co. | F5: 19.5
A6: Unrecorded transfer | C6: UPS Freight
A7: Theft or loss | C7: Customer pickup | E7: Rates are illustrative, not quotes.
A8: Under review
